2022-11-23 08:22:43,138 ERROR Internal Server Error: /posts/create/ D:\Python\DjangoProjects\NewsPaper\venv\lib\site-packages\django\utils\log.py (<class 'kombu.exceptions.OperationalError'>, OperationalError('Error 10061 connecting to localhost:6379. Подключение не установлено, т.к. конечный компьютер отверг запрос на подключение.'), <traceback object at 0x000001DAC77C7740>)
Traceback (most recent call last):
  File "D:\Python\DjangoProjects\NewsPaper\venv\lib\site-packages\redis\connection.py", line 611, in connect
    sock = self.retry.call_with_retry(
  File "D:\Python\DjangoProjects\NewsPaper\venv\lib\site-packages\redis\retry.py", line 46, in call_with_retry
    return do()
  File "D:\Python\DjangoProjects\NewsPaper\venv\lib\site-packages\redis\connection.py", line 612, in <lambda>
    lambda: self._connect(), lambda error: self.disconnect(error)
  File "D:\Python\DjangoProjects\NewsPaper\venv\lib\site-packages\redis\connection.py", line 677, in _connect
    raise err
  File "D:\Python\DjangoProjects\NewsPaper\venv\lib\site-packages\redis\connection.py", line 665, in _connect
    sock.connect(socket_address)
ConnectionRefusedError: [WinError 10061] Подключение не установлено, т.к. конечный компьютер отверг запрос на подключение

During handling of the above exception, another exception occurred:

Traceback (most recent call last):
  File "D:\Python\DjangoProjects\NewsPaper\venv\lib\site-packages\celery\backends\redis.py", line 119, in reconnect_on_error
    yield
  File "D:\Python\DjangoProjects\NewsPaper\venv\lib\site-packages\celery\backends\redis.py", line 169, in _consume_from
    self._pubsub.subscribe(key)
  File "D:\Python\DjangoProjects\NewsPaper\venv\lib\site-packages\redis\client.py", line 1592, in subscribe
    ret_val = self.execute_command("SUBSCRIBE", *new_channels.keys())
  File "D:\Python\DjangoProjects\NewsPaper\venv\lib\site-packages\redis\client.py", line 1433, in execute_command
    self.connection = self.connection_pool.get_connection(
  File "D:\Python\DjangoProjects\NewsPaper\venv\lib\site-packages\redis\connection.py", line 1387, in get_connection
    connection.connect()
  File "D:\Python\DjangoProjects\NewsPaper\venv\lib\site-packages\redis\connection.py", line 617, in connect
    raise ConnectionError(self._error_message(e))
redis.exceptions.ConnectionError: Error 10061 connecting to localhost:6379. Подключение не установлено, т.к. конечный компьютер отверг запрос на подключение.

During handling of the above exception, another exception occurred:

Traceback (most recent call last):
  File "D:\Python\DjangoProjects\NewsPaper\venv\lib\site-packages\redis\connection.py", line 611, in connect
    sock = self.retry.call_with_retry(
  File "D:\Python\DjangoProjects\NewsPaper\venv\lib\site-packages\redis\retry.py", line 46, in call_with_retry
    return do()
  File "D:\Python\DjangoProjects\NewsPaper\venv\lib\site-packages\redis\connection.py", line 612, in <lambda>
    lambda: self._connect(), lambda error: self.disconnect(error)
  File "D:\Python\DjangoProjects\NewsPaper\venv\lib\site-packages\redis\connection.py", line 677, in _connect
    raise err
  File "D:\Python\DjangoProjects\NewsPaper\venv\lib\site-packages\redis\connection.py", line 665, in _connect
    sock.connect(socket_address)
ConnectionRefusedError: [WinError 10061] Подключение не установлено, т.к. конечный компьютер отверг запрос на подключение

During handling of the above exception, another exception occurred:

Traceback (most recent call last):
  File "D:\Python\DjangoProjects\NewsPaper\venv\lib\site-packages\kombu\connection.py", line 446, in _reraise_as_library_errors
    yield
  File "D:\Python\DjangoProjects\NewsPaper\venv\lib\site-packages\celery\app\base.py", line 787, in send_task
    self.backend.on_task_call(P, task_id)
  File "D:\Python\DjangoProjects\NewsPaper\venv\lib\site-packages\celery\backends\redis.py", line 365, in on_task_call
    self.result_consumer.consume_from(task_id)
  File "D:\Python\DjangoProjects\NewsPaper\venv\lib\site-packages\celery\backends\redis.py", line 161, in consume_from
    return self.start(task_id)
  File "D:\Python\DjangoProjects\NewsPaper\venv\lib\site-packages\celery\backends\redis.py", line 139, in start
    self._consume_from(initial_task_id)
  File "D:\Python\DjangoProjects\NewsPaper\venv\lib\site-packages\celery\backends\redis.py", line 169, in _consume_from
    self._pubsub.subscribe(key)
  File "D:\Python\lib\contextlib.py", line 137, in __exit__
    self.gen.throw(typ, value, traceback)
  File "D:\Python\DjangoProjects\NewsPaper\venv\lib\site-packages\celery\backends\redis.py", line 122, in reconnect_on_error
    self._ensure(self._reconnect_pubsub, ())
  File "D:\Python\DjangoProjects\NewsPaper\venv\lib\site-packages\celery\backends\redis.py", line 376, in ensure
    return retry_over_time(
  File "D:\Python\DjangoProjects\NewsPaper\venv\lib\site-packages\kombu\utils\functional.py", line 312, in retry_over_time
    return fun(*args, **kwargs)
  File "D:\Python\DjangoProjects\NewsPaper\venv\lib\site-packages\celery\backends\redis.py", line 106, in _reconnect_pubsub
    metas = self.backend.client.mget(self.subscribed_to)
  File "D:\Python\DjangoProjects\NewsPaper\venv\lib\site-packages\redis\commands\core.py", line 1893, in mget
    return self.execute_command("MGET", *args, **options)
  File "D:\Python\DjangoProjects\NewsPaper\venv\lib\site-packages\redis\client.py", line 1235, in execute_command
    conn = self.connection or pool.get_connection(command_name, **options)
  File "D:\Python\DjangoProjects\NewsPaper\venv\lib\site-packages\redis\connection.py", line 1387, in get_connection
    connection.connect()
  File "D:\Python\DjangoProjects\NewsPaper\venv\lib\site-packages\redis\connection.py", line 617, in connect
    raise ConnectionError(self._error_message(e))
redis.exceptions.ConnectionError: Error 10061 connecting to localhost:6379. Подключение не установлено, т.к. конечный компьютер отверг запрос на подключение.

The above exception was the direct cause of the following exception:

Traceback (most recent call last):
  File "D:\Python\DjangoProjects\NewsPaper\venv\lib\site-packages\django\core\handlers\exception.py", line 55, in inner
    response = get_response(request)
  File "D:\Python\DjangoProjects\NewsPaper\venv\lib\site-packages\django\core\handlers\base.py", line 197, in _get_response
    response = wrapped_callback(request, *callback_args, **callback_kwargs)
  File "D:\Python\DjangoProjects\NewsPaper\venv\lib\site-packages\django\views\generic\base.py", line 103, in view
    return self.dispatch(request, *args, **kwargs)
  File "D:\Python\DjangoProjects\NewsPaper\venv\lib\site-packages\django\contrib\auth\mixins.py", line 109, in dispatch
    return super().dispatch(request, *args, **kwargs)
  File "D:\Python\DjangoProjects\NewsPaper\venv\lib\site-packages\django\views\generic\base.py", line 142, in dispatch
    return handler(request, *args, **kwargs)
  File "D:\Python\DjangoProjects\NewsPaper\venv\lib\site-packages\django\views\generic\edit.py", line 184, in post
    return super().post(request, *args, **kwargs)
  File "D:\Python\DjangoProjects\NewsPaper\venv\lib\site-packages\django\views\generic\edit.py", line 153, in post
    return self.form_valid(form)
  File "D:\Python\DjangoProjects\NewsPaper\venv\lib\site-packages\django\views\generic\edit.py", line 135, in form_valid
    self.object = form.save()
  File "D:\Python\DjangoProjects\NewsPaper\venv\lib\site-packages\django\forms\models.py", line 549, in save
    self._save_m2m()
  File "D:\Python\DjangoProjects\NewsPaper\venv\lib\site-packages\django\forms\models.py", line 530, in _save_m2m
    f.save_form_data(self.instance, cleaned_data[f.name])
  File "D:\Python\DjangoProjects\NewsPaper\venv\lib\site-packages\django\db\models\fields\related.py", line 1966, in save_form_data
    getattr(instance, self.attname).set(data)
  File "D:\Python\DjangoProjects\NewsPaper\venv\lib\site-packages\django\db\models\fields\related_descriptors.py", line 1152, in set
    self.add(*new_objs, through_defaults=through_defaults)
  File "D:\Python\DjangoProjects\NewsPaper\venv\lib\site-packages\django\db\models\fields\related_descriptors.py", line 1070, in add
    self._add_items(
  File "D:\Python\DjangoProjects\NewsPaper\venv\lib\site-packages\django\db\models\fields\related_descriptors.py", line 1335, in _add_items
    signals.m2m_changed.send(
  File "D:\Python\DjangoProjects\NewsPaper\venv\lib\site-packages\django\dispatch\dispatcher.py", line 176, in send
    return [
  File "D:\Python\DjangoProjects\NewsPaper\venv\lib\site-packages\django\dispatch\dispatcher.py", line 177, in <listcomp>
    (receiver, receiver(signal=self, sender=sender, **named))
  File "D:\Python\DjangoProjects\NewsPaper\news\signals.py", line 15, in task_notify_about_new_post
    notify_about_new_post.apply_async([instance.id], countdown=10)
  File "D:\Python\DjangoProjects\NewsPaper\venv\lib\site-packages\celery\app\task.py", line 575, in apply_async
    return app.send_task(
  File "D:\Python\DjangoProjects\NewsPaper\venv\lib\site-packages\celery\app\base.py", line 788, in send_task
    amqp.send_task_message(P, name, message, **options)
  File "D:\Python\lib\contextlib.py", line 137, in __exit__
    self.gen.throw(typ, value, traceback)
  File "D:\Python\DjangoProjects\NewsPaper\venv\lib\site-packages\kombu\connection.py", line 450, in _reraise_as_library_errors
    raise ConnectionError(str(exc)) from exc
kombu.exceptions.OperationalError: Error 10061 connecting to localhost:6379. Подключение не установлено, т.к. конечный компьютер отверг запрос на подключение.
2022-11-23 08:22:43,212 ERROR "POST /posts/create/ HTTP/1.1" 500 316305 D:\Python\DjangoProjects\NewsPaper\venv\lib\site-packages\django\core\servers\basehttp.py None
